Workbook

Sheet تعليمات
A1: مجموعة الاختبار — testset
A3: ■ الغرض
A4: هذه المجموعة هي الدليل الذي تقدّمه للجنة: يشغّل سكربت القياس المدقّق عليها ويحسب الدقة ونسبة الامتناع الصحيح. جودتها تساوي مصداقية أرقامك.
A6: ■ الحجم: 200 حالة موزعة على 9 فئات (انظر ورقة «التقدّم» لترى ما أنجزت من كل فئة).
A8: ■ طريقة التعبئة
A9: 1) النص: فقرة واقعية كاملة (من منشور أو مخطوطة أو ترجمة)، تحوي استشهادًا واحدًا رئيسيًا. لا تكتب جملة معزولة.
A10: 2) الفئة واللغة والنوع والحالة المتوقعة: من القوائم المنسدلة.
A11: 3) المرجع المتوقع: للآيات «رقم السورة:رقم الآية» مثل 51:56، وللأحاديث معرّف الحديث في الفهرس مثل h-012. اتركه فارغًا للفئتين C8 وC9.
A12: 4) الحالة المتوقعة للأحاديث تُؤخذ من أحكام الفهرس: إن اختلفت أحكام المحدّثين فاكتب HADITH_MULTIPLE_RULINGS.
A13: 5) المراجعة: يراجع المراجع الشرعي كل حالة ويختار «مقبول» أو «يحتاج تعديل». لا تُحتسب في القياس إلا الحالات المقبولة.
A15: ■ التقسيم (split)
A16: المعرّفات المجهّزة مقسّمة مسبقًا: كل رابع حالة dev (50 حالة لضبط المدقّق)، والباقي test (150 حالة للقياس النهائي فقط). وزّع الفئات على الصفوف بحيث يكون في dev نحو ربع كل فئة؛ ورقة «التقدّم» تريك ذلك.
... A22: ■ الصفوف الرمادية أمثلة (المعرّف EX) ويتجاهلها السكربت.

Sheet الحالات
A1: المعرّف * | B1: التقسيم * | C1: الفئة * | D1: اللغة * | E1: النوع * | F1: الوحدة * | G1: النص (فقرة واقعية) * | H1: الحالة المتوقعة * | I1: المرجع المتوقع | J1: مصدر النص | K1: المراجع | L1: نتيجة المراجعة * | M1: ملاحظات
A2: id | B2: split | C2: category | D2: lang | E2: kind | F2: target_module | G2: text | H2: expected_status | I2: expected_ref | J2: text_origin | K2: reviewed_by | L2: review_status | M2: notes
A3: EX-1 | B3: dev | C3: C1 آيات عربية صحيحة | D3: ar | E3: quran | F3: verifier | G3: غاية وجود الإنسان في الإسلام واضحة، قال تعالى: ﴿وَمَا خَلَقْتُ الْجِنَّ وَالْإِنسَ إِلَّا لِيَعْبُدُونِ﴾، فالعبادة بمعناها الشامل هي مقصد الخلق. | H3: QURAN_VERIFIED | I3: 51:56 | J3: مثال | L3: مقبول
A4: EX-2 | B4: dev | C4: C2 آيات محرفة اللفظ | D4: ar | E4: quran | F4: verifier | G4: وقد بيّن القرآن الغاية من الخلق بقوله: «وما خلقنا الجن والإنس إلا ليعبدون». | H4: QURAN_WORDING_DIFFERS | I4: 51:56 | J4: مثال | L4: مقبول | M4: «خلقنا» بدل «خلقتُ»
A5: t-001 | B5: test | C5: C1 آيات عربية صحيحة | D5: ar | E5: quran | F5: verifier | G5: من أعظم ما يطمئن به القلب أن الله تعالى قال في كتابه: ﴿رَبَّنَا لَا تُزِغْ قُلُوبَنَا بَعْدَ إِذْ هَدَيْتَنَا وَهَبْ لَنَا مِنْ لَدُنْكَ رَحْمَةً إِنَّكَ أَنْتَ الْوَهَّابُ﴾، فهذه الآية تفتح باب الأمل لكل من ضاقت به الدنيا. | H5: QURAN_VERIFIED | I5: 3:8 | J5: نص الآية من فهرس المصحف في المكتبة الشاملة (إملائي) | K5: محمد سجاد | L5: مقبول
A6: t-002 | B6: test | C6: C1 آيات عربية صحيحة | D6: ar | E6: quran | F6: verifier | G6: يقول الله عز وجل: فبما رحمة من الله لنت لهم ولو كنت فظا غليظ القلب لانفضوا من حولك فاعف عنهم واستغفر لهم وشاورهم في الأمر فإذا عزمت فتوكل على الله إن الله يحب المتوكلين. وفي هذا تذكير لنا بأن الرحمة أصل في تعامل المسلم مع الناس. | H6: QURAN_VERIFIED | I6: 3:159 | J6: نص الآية من فهرس المصحف في المكتبة الشاملة (إملائي)، بلا تشكيل | K6: محمد سجاد | L6: مقبول
A7: t-003 | B7: test | C7: C1 آيات عربية صحيحة | D7: ar | E7: quran | F7: verifier | G7: أخي الكريم، تأمل قوله تعالى: «فَأَمَّا الَّذِينَ آمَنُوا بِاللَّهِ وَاعْتَصَمُوا بِهِ فَسَيُدْخِلُهُمْ فِي رَحْمَةٍ مِنْهُ وَفَضْلٍ وَيَهْدِيهِمْ إِلَيْهِ صِرَاطًا مُسْتَقِيمًا»، ثم انظر كيف ينبغي أن يكون حالنا مع إخواننا في هذا المجتمع. | H7: QURAN_VERIFIED | I7: 4:175 | J7: نص الآية من فهرس المصحف في المكتبة الشاملة (إملائي) | K7: محمد سجاد | L7: مقبول
A8: t-004 | B8: dev | C8: C1 آيات عربية صحيحة | D8: ar | E8: quran | F8: verifier | G8: في درس الأمس بالمركز تحدثنا عن قول الله سبحانه: ﴿فإن كذبوك فقل ربكم ذو رحمة واسعة ولا يرد بأسه عن القوم المجرمين﴾، وكيف نشرح معناها لمن لا يعرف العربية. | H8: QURAN_VERIFIED | I8: 6:147 | J8: نص الآية من فهرس المصحف في المكتبة الشاملة (إملائي)، بلا تشكيل | K8: محمد سجاد | L8: مقبول
A9: t-005 | B9: test | C9: C1 آيات عربية صحيحة | D9: ar | E9: quran | F9: verifier | G9: قال الله تعالى: قَالَ وَمَنْ يَقْنَطُ مِنْ رَحْمَةِ رَبِّهِ إِلَّا الضَّالُّونَ صدق الله العظيم. | H9: QURAN_VERIFIED | I9: 15:56 | J9: نص الآية من فهرس المصحف في المكتبة الشاملة (إملائي) | K9: محمد سجاد | L9: مقبول
A10: t-006 | B10: test | C10: C1 آيات عربية صحيحة | D10: ar | E10: quran | F10: verifier | G10: منشور اليوم: ﴿وإما تعرضن عنهم ابتغاء رحمة من ربك ترجوها فقل لهم قولا ميسورا﴾ — شاركها مع من تحب ولا تنس الدعاء لنا. | H10: QURAN_VERIFIED | I10: 17:28 | J10: نص الآية من فهرس المصحف في المكتبة الشاملة (إملائي)، بلا تشكيل | K10: محمد سجاد | L10: مقبول
A11: t-007 | B11: test | C11: C1 آيات عربية صحيحة | D11: ar | E11: quran | F11: verifier | G11: ومن الأدلة على ذلك قوله تعالى: إِذْ أَوَى الْفِتْيَةُ إِلَى الْكَهْفِ فَقَالُوا رَبَّنَا آتِنَا مِنْ لَدُنْكَ رَحْمَةً وَهَيِّئْ لَنَا مِنْ أَمْرِنَا رَشَدًا، وهي آية جامعة يحسن بالداعية أن يحفظها. | H11: QURAN_VERIFIED | I11: 18:10 | J11: نص الآية من فهرس المصحف في المكتبة الشاملة (إملائي) | L11: لم يراجع
A12: t-008 | B12: dev | C12: C1 آيات عربية صحيحة | D12: ar | E12: quran | F12: verifier | G12: من أعظم ما يطمئن به القلب أن الله تعالى قال في كتابه: ﴿وما أرسلناك إلا رحمة للعالمين﴾، فهذه الآية تفتح باب الأمل لكل من ضاقت به الدنيا. | H12: QURAN_VERIFIED | I12: 21:107 | J12: نص الآية من فهرس المصحف في المكتبة الشاملة (إملائي)، بلا تشكيل | L12: مقبول
A13: t-009 | B13: test | C13: C1 آيات عربية صحيحة | D13: ar | E13: quran | F13: verifier | G13: يقول الله عز وجل: مَا يَفْتَحِ اللَّهُ لِلنَّاسِ مِنْ رَحْمَةٍ فَلَا مُمْسِكَ لَهَا وَمَا يُمْسِكْ فَلَا مُرْسِلَ لَهُ مِنْ بَعْدِهِ وَهُوَ الْعَزِيزُ الْحَكِيمُ. وفي هذا تذكير لنا بأن الرحمة أصل في تعامل المسلم مع الناس. | H13: QURAN_VERIFIED | I13: 35:2 | J13: نص الآية من فهرس المصحف في المكتبة الشاملة (إملائي) | L13: لم يراجع
A14: t-010 | B14: test | C14: C1 آيات عربية صحيحة | D14: ar | E14: quran | F14: verifier | G14: أخي الكريم، تأمل قوله تعالى: «أمن هو قانت آناء الليل ساجدا وقائما يحذر الآخرة ويرجو رحمة ربه قل هل يستوي الذين يعلمون والذين لا يعلمون إنما يتذكر أولو الألباب»، ثم انظر كيف ينبغي أن يكون حالنا مع إخواننا في هذا المجتمع. | H14: QURAN_VERIFIED | I14: 39:9 | J14: نص الآية من فهرس المصحف في المكتبة الشاملة (إملائي)، بلا تشكيل | L14: لم يراجع
A15: t-011 | B15: test | C15: C1 آيات عربية صحيحة | D15: ar | E15: quran | F15: verifier | G15: في درس الأمس بالمركز تحدثنا عن قول الله سبحانه: ﴿قُلْ يَاعِبَادِيَ الَّذِينَ أَسْرَفُوا عَلَى أَنْفُسِهِمْ لَا تَقْنَطُوا مِنْ رَحْمَةِ اللَّهِ إِنَّ اللَّهَ يَغْفِرُ الذُّنُوبَ جَمِيعًا إِنَّهُ هُوَ الْغَفُورُ الرَّحِيمُ﴾، وكيف نشرح معناها لمن لا يعرف العربية. | H15: QURAN_VERIFIED | I15: 39:53 | J15: نص الآية من فهرس المصحف في المكتبة الشاملة (إملائي) | K15: محمد سجاد | L15: مقبول
A16: t-012 | B16: dev | C16: C1 آيات عربية صحيحة | D16: ar | E16: quran | F16: verifier | G16: قال الله تعالى: الذين يحملون العرش ومن حوله يسبحون بحمد ربهم ويؤمنون به ويستغفرون للذين آمنوا ربنا وسعت كل شيء رحمة وعلما فاغفر للذين تابوا واتبعوا سبيلك وقهم عذاب الجحيم صدق الله العظيم. | H16: QURAN_VERIFIED | I16: 40:7 | J16: نص الآية من فهرس المصحف في المكتبة الشاملة (إملائي)، بلا تشكيل | K16: محمد سجاد | L16: مقبول
A17: t-013 | B17: test | C17: C1 آيات عربية صحيحة | D17: ar | E17: quran | F17: verifier | G17: منشور اليوم: ﴿رَحْمَةً مِنْ رَبِّكَ إِنَّهُ هُوَ السَّمِيعُ الْعَلِيمُ﴾ — شاركها مع من تحب ولا تنس الدعاء لنا. | H17: QURAN_VERIFIED | I17: 44:6 | J17: نص الآية من فهرس المصحف في المكتبة الشاملة (إملائي) | L17: مقبول
A18: t-014 | B18: test | C18: C1 آيات عربية صحيحة | D18: ar | E18: quran | F18: verifier | G18: ومن الأدلة على ذلك قوله تعالى: وَإِذَا سَأَلَكَ عِبَادِي عَنِّي فَإِنِّي قَرِيبٌۖ أُجِيبُ دَعۡوَةَ ٱلدَّاعِ إِذَا دَعَانِۖ فَلۡيَسۡتَجِيبُواْ لِي وَلۡيُؤۡمِنُواْ بِي لَعَلَّهُمۡ يَرۡشُدُونَ، وهي آية جامعة يحسن بالداعية أن يحفظها. | H18: QURAN_VERIFIED | I18: 2:186 | J18: نص الآية بالرسم العثماني من QuranEnc عبر حزمة quran-json | L18: مقبول
A19: t-015 | B19: test | C19: C1 آيات عربية صحيحة | D19: ar | E19: quran | F19: verifier | G19: من أعظم ما يطمئن به القلب أن الله تعالى قال في كتابه: ﴿ٱلَّذِينَ ءَامَنُواْ وَتَطۡمَئِنُّ قُلُوبُهُم بِذِكۡرِ ٱللَّهِۗ أَلَا بِذِكۡرِ ٱللَّهِ تَطۡمَئِنُّ ٱلۡقُلُوبُ﴾، فهذه الآية تفتح باب الأمل لكل من ضاقت به الدنيا. | H19: QURAN_VERIFIED | I19: 13:28 | J19: نص الآية بالرسم العثماني من QuranEnc عبر حزمة quran-json | L19: مقبول
A20: t-016 | B20: dev | C20: C1 آيات عربية صحيحة | D20: ar | E20: quran | F20: verifier | G20: يقول الله عز وجل: يَـٰٓأَيُّهَا ٱلنَّاسُ إِنَّا خَلَقۡنَٰكُم مِّن ذَكَرٖ وَأُنثَىٰ وَجَعَلۡنَٰكُمۡ شُعُوبٗا وَقَبَآئِلَ لِتَعَارَفُوٓاْۚ إِنَّ أَكۡرَمَكُمۡ عِندَ ٱللَّهِ أَتۡقَىٰكُمۡۚ إِنَّ ٱللَّهَ عَلِيمٌ خَبِيرٞ. تبيّن الآية أن معيار الكرامة عند الله هو التقوى. | H20: QURAN_VERIFIED | I20: 49:13 | J20: نص الآية بالرسم العثماني من QuranEnc عبر حزمة quran-json | K20: محمد سجاد | L20: مقبول
A21: t-017 | B21: test | C21: C1 آيات عربية صحيحة | D21: ar | E21: quran | F21: verifier | G21: أخي الكريم، تأمل قوله تعالى: «ٱدۡعُ إِلَىٰ سَبِيلِ رَبِّكَ بِٱلۡحِكۡمَةِ وَٱلۡمَوۡعِظَةِ ٱلۡحَسَنَةِۖ وَجَٰدِلۡهُم بِٱلَّتِي هِيَ أَحۡسَنُۚ إِنَّ رَبَّكَ هُوَ أَعۡلَمُ بِمَن ضَلَّ عَن سَبِيلِهِۦ وَهُوَ أَعۡلَمُ بِٱلۡمُهۡتَدِينَ»، ثم انظر كيف ينبغي أن يكون حالنا مع إخواننا في هذا المجتمع. | H21: QURAN_VERIFIED | I21: 16:125 | J21: نص الآية بالرسم العثماني من QuranEnc عبر حزمة quran-json | K21: محمد سجاد | L21: مقبول
A22: t-018 | B22: test | C22: C1 آيات عربية صحيحة | D22: ar | E22: quran | F22: verifier | G22: في درس الأمس بالمركز تحدثنا عن قول الله سبحانه: ﴿لَآ إِكۡرَاهَ فِي ٱلدِّينِۖ قَد تَّبَيَّنَ ٱلرُّشۡدُ مِنَ ٱلۡغَيِّۚ فَمَن يَكۡفُرۡ بِٱلطَّـٰغُوتِ وَيُؤۡمِنۢ بِٱللَّهِ فَقَدِ ٱسۡتَمۡسَكَ بِٱلۡعُرۡوَةِ ٱلۡوُثۡقَىٰ لَا ٱنفِصَامَ لَهَاۗ وَٱللَّهُ سَمِيعٌ عَلِيمٌ﴾، وكيف نشرح معناها لمن لا يعرف العربية. | H22: QURAN_VERIFIED | I22: 2:256 | J22: نص الآية بالرسم العثماني من QuranEnc عبر حزمة quran-json | L22: لم يراجع
A23: t-019 | B23: test | C23: C1 آيات عربية صحيحة | D23: ar | E23: quran | F23: verifier | G23: قال الله تعالى: قُلۡ هُوَ ٱللَّهُ أَحَدٌ صدق الله العظيم. فلنجعل هذه الآية شعارنا في دعوتنا هذا الأسبوع. | H23: QURAN_VERIFIED | I23: 112:1 | J23: نص الآية بالرسم العثماني من QuranEnc عبر حزمة quran-json | L23: لم يراجع
A24: t-020 | B24: dev | C24: C1 آيات عربية صحيحة | D24: ar | E24: quran | F24: verifier | G24: منشور اليوم: ﴿كُلُّ نَفۡسٖ ذَآئِقَةُ ٱلۡمَوۡتِۗ وَإِنَّمَا تُوَفَّوۡنَ أُجُورَكُمۡ يَوۡمَ ٱلۡقِيَٰمَةِۖ فَمَن زُحۡزِحَ عَنِ ٱلنَّارِ وَأُدۡخِلَ ٱلۡجَنَّةَ فَقَدۡ فَازَۗ وَمَا ٱلۡحَيَوٰةُ ٱلدُّنۡيَآ إِلَّا مَتَٰعُ ٱلۡغُرُورِ﴾ — شاركها مع من تحب ولا تنس الدعاء لنا. | H24: QURAN_VERIFIED | I24: 3:185 | J24: نص الآية بالرسم العثماني من QuranEnc عبر حزمة quran-json | K24: محمد سجاد | L24: مقبول
A25: t-021 | B25: test | C25: C1 آيات عربية صحيحة | D25: ar | E25: quran | F25: verifier | G25: ومن الأدلة على ذلك قوله تعالى: لَّا يَنۡهَىٰكُمُ ٱللَّهُ عَنِ ٱلَّذِينَ لَمۡ يُقَٰتِلُوكُمۡ فِي ٱلدِّينِ وَلَمۡ يُخۡرِجُوكُم مِّن دِيَٰرِكُمۡ أَن تَبَرُّوهُمۡ وَتُقۡسِطُوٓاْ إِلَيۡهِمۡۚ إِنَّ ٱللَّهَ يُحِبُّ ٱلۡمُقۡسِطِينَ، وهي آية جامعة يحسن بالداعية أن يحفظها. | H25: QURAN_VERIFIED | I25: 60:8 | J25: نص الآية بالرسم العثماني من QuranEnc عبر حزمة quran-json | L25: لم يراجع
A26: t-022 | B26: test | C26: C1 آيات عربية صحيحة | D26: ar | E26: quran | F26: verifier | G26: من أعظم ما يطمئن به القلب أن الله تعالى قال في كتابه: ﴿وَٱلَّذِينَ جَٰهَدُواْ فِينَا لَنَهۡدِيَنَّهُمۡ سُبُلَنَاۚ وَإِنَّ ٱللَّهَ لَمَعَ ٱلۡمُحۡسِنِينَ﴾، فهذه الآية تفتح باب الأمل لكل من ضاقت به الدنيا. | H26: QURAN_VERIFIED | I26: 29:69 | J26: نص الآية بالرسم العثماني من QuranEnc عبر حزمة quran-json | L26: لم يراجع
A27: t-023 | B27: test | C27: C1 آيات عربية صحيحة | D27: ar | E27: quran | F27: verifier | G27: يقول الله عز وجل: يَـٰٓأَيُّهَا ٱلَّذِينَ ءَامَنُواْ كُتِبَ عَلَيۡكُمُ ٱلصِّيَامُ كَمَا كُتِبَ عَلَى ٱلَّذِينَ مِن قَبۡلِكُمۡ لَعَلَّكُمۡ تَتَّقُونَ. وفي هذه الآية دلالة على فرضية الصيام على المسلمين، وكما تدل على مقصد أكبر للصيام. | H27: QURAN_VERIFIED | I27: 2:183 | J27: نص الآية بالرسم العثماني من QuranEnc عبر حزمة quran-json | K27: محمد سجاد | L27: مقبول
A28: t-024 | B28: dev | C28: C1 آيات عربية صحيحة | D28: ar | E28: quran | F28: verifier | G28: أخي الكريم، تأمل قوله تعالى: «۞وَقَضَىٰ رَبُّكَ أَلَّا تَعۡبُدُوٓاْ إِلَّآ إِيَّاهُ وَبِٱلۡوَٰلِدَيۡنِ إِحۡسَٰنًاۚ إِمَّا يَبۡلُغَنَّ عِندَكَ ٱلۡكِبَرَ أَحَدُهُمَآ أَوۡ كِلَاهُمَا فَلَا تَقُل لَّهُمَآ أُفّٖ وَلَا تَنۡهَرۡهُمَا وَقُل لَّهُمَا قَوۡلٗا كَرِيمٗا»، ثم انظر كيف ينبغي أن يكون تعاملنا مع الوالدين. | H28: QURAN_VERIFIED | I28: 17:23 | J28: نص الآية بالرسم العثماني من QuranEnc عبر حزمة quran-json | K28: محمد سجاد | L28: مقبول
A29: t-025 | B29: test | C29: C1 آيات عربية صحيحة | D29: ar | E29: quran | F29: verifier | G29: في درس الأمس بالمركز تحدثنا عن قول الله سبحانه: ﴿يَـٰٓأَيُّهَا ٱلنَّاسُ ٱتَّقُواْ رَبَّكُمُ ٱلَّذِي خَلَقَكُم مِّن نَّفۡسٖ وَٰحِدَةٖ وَخَلَقَ مِنۡهَا زَوۡجَهَا وَبَثَّ مِنۡهُمَا رِجَالٗا كَثِيرٗا وَنِسَآءٗۚ وَٱتَّقُواْ ٱللَّهَ ٱلَّذِي تَسَآءَلُونَ بِهِۦ وَٱلۡأَرۡحَامَۚ إِنَّ ٱللَّهَ كَانَ عَلَيۡكُمۡ رَقِيبٗا﴾، وكيف نشرح معناها لمن لا يعرف العربية. | H29: QURAN_VERIFIED | I29: 4:1 | J29: نص الآية بالرسم العثماني من QuranEnc عبر حزمة quran-json | L29: لم يراجع
A30: t-026 | B30: test | C30: C2 آيات محرفة اللفظ | D30: ar | E30: quran | F30: verifier | G30: في درس الأمس بالمركز تحدثنا عن قول الله سبحانه: ﴿وَأَمَّا الَّذِينَ ابْيَضَّتْ وُجُوهُهُمْ فَفِي رَحْمَةِ اللَّهِ هُمْ فِيهَا مُخَلَّدُونَ﴾، وكيف نشرح معناها لمن لا يعرف العربية. | H30: QURAN_WORDING_DIFFERS | I30: 3:107 | J30: آية من فهرس المصحف في الشاملة غُيّرت فيها كلمة واحدة عمدًا | K30: محمد سجاد | L30: مقبول | M30: المحرّف: «مخلدون» بدل «خالدون»
A31: t-027 | B31: test | C31: C2 آيات محرفة اللفظ | D31: ar | E31: quran | F31: verifier | G31: قال الله تعالى: من يصرف عنه يومئذ فقد رحمه وذلك الفوز العظيم صدق الله العظيم. فلنجعل هذه الآية شعارنا في دعوتنا هذا الأسبوع. | H31: QURAN_WORDING_DIFFERS | I31: 6:16 | J31: آية من فهرس المصحف في الشاملة غُيّرت فيها كلمة واحدة عمدًا | L31: لم يراجع | M31: المحرّف: «العظيم» بدل «المبين»
A32: t-028 | B32: test | C32: C2 آيات محرفة اللفظ | D32: ar | E32: quran | F32: verifier | G32: منشور اليوم: ﴿وَلَئِنْ أَذَقْنَا الْإِنْسَانَ مِنَّا رَحْمَةً ثُمَّ نَزَعْنَاهَا مِنْهُ إِنَّهُ لَقَنُوطٌ كَفُورٌ﴾ — شاركها مع من تحب ولا تنس الدعاء لنا. | H32: QURAN_WORDING_DIFFERS | I32: 11:9 | J32: آية من فهرس المصحف في الشاملة غُيّرت فيها كلمة واحدة عمدًا | L32: لم يراجع | M32: المحرّف: «لقنوط» بدل «ليئوس»
A33: t-029 | B33: dev | C33: C2 آيات محرفة اللفظ | D33: ar | E33: quran | F33: verifier | G33: ومن الأدلة على ذلك قوله تعالى: إلا رحمة من ربك إن فضله كان عليك عظيما، وهي آية جامعة يحسن بالداعية أن يحفظها. | H33: QURAN_WORDING_DIFFERS | I33: 17:87 | J33: آية من فهرس المصحف في الشاملة غُيّرت فيها كلمة واحدة عمدًا | K33: محمد سجاد | L33: مقبول | M33: المحرّف: «عظيما» بدل «كبيرا»
A34: t-030 | B34: test | C34: C2 آيات محرفة اللفظ | D34: ar | E34: quran | F34: verifier | G34: من أعظم ما يطمئن به القلب أن الله تعالى قال في كتابه: ﴿قُلْ لَوْ أَنْتُمْ تَمْلِكُونَ خَزَائِنَ رَحْمَةِ رَبِّي إِذًا لَأَمْسَكْتُمْ خَشْيَةَ الْإِنْفَاقِ وَكَانَ الْإِنْسَانُ كَفُورًا﴾، فهذه الآية تفتح باب الأمل لكل من ضاقت به الدنيا. | H34: QURAN_WORDING_DIFFERS | I34: 17:100 | J34: آية من فهرس المصحف في الشاملة غُيّرت فيها كلمة واحدة عمدًا | K34: محمد سجاد | L34: مقبول | M34: المحرّف: «كفورا» بدل «قتورا»
A35: t-031 | B35: test | C35: C2 آيات محرفة اللفظ | D35: ar | E35: quran | F35: verifier | G35: يقول الله عز وجل: فوجدا عبدا من عبادنا آتيناه رحمة من عندنا وعلمناه من عندنا علما. وفي هذا تذكير لنا بأن الرحمة أصل في تعامل المسلم مع الناس. | H35: QURAN_WORDING_DIFFERS | I35: 18:65 | J35: آية من فهرس المصحف في الشاملة غُيّرت فيها كلمة واحدة عمدًا | L35: لم يراجع | M35: المحرّف: «من عندنا» بدل «من لدنا»
A36: t-032 | B36: test | C36: C2 آيات محرفة اللفظ | D36: ar | E36: quran | F36: verifier | G36: أخي الكريم، تأمل قوله تعالى: «قَالَ هَذَا رَحْمَةٌ مِنْ رَبِّي فَإِذَا جَاءَ وَعْدُ رَبِّي جَعَلَهُ دَكًّا وَكَانَ وَعْدُ رَبِّي حَقًّا»، ثم انظر كيف ينبغي أن يكون حالنا مع إخواننا في هذا المجتمع. | H36: QURAN_WORDING_DIFFERS | I36: 18:98 | J36: آية من فهرس المصحف في الشاملة غُيّرت فيها كلمة واحدة عمدًا | L36: لم يراجع | M36: المحرّف: «دكا» بدل «دكاء»
A37: t-033 | B37: dev | C37: C2 آيات محرفة اللفظ | D37: ar | E37: quran | F37: verifier | G37: في درس الأمس بالمركز تحدثنا عن قول الله سبحانه: ﴿فاستجبنا له فكشفنا ما به من ضر وآتيناه أهله ومثلهم معهم رحمة من عندنا وذكرى للمؤمنين﴾، وكيف نشرح معناها لمن لا يعرف العربية. | H37: QURAN_WORDING_DIFFERS | I37: 21:84 | J37: آية من فهرس المصحف في الشاملة غُيّرت فيها كلمة واحدة عمدًا | K37: محمد سجاد | L37: مقبول | M37: المحرّف: «للمؤمنين» بدل «للعابدين»
A38: t-034 | B38: test | C38: C2 آيات محرفة اللفظ | D38: ar | E38: quran | F38: verifier | G38: قال الله تعالى: وَمَا كُنْتَ تَرْجُو أَنْ يُلْقَى إِلَيْكَ الْكِتَابُ إِلَّا رَحْمَةً مِنْ رَبِّكَ فَلَا تَكُونَنَّ نَصِيرًا لِلْكَافِرِينَ صدق الله العظيم. فلنجعل هذه الآية شعارنا في دعوتنا هذا الأسبوع. | H38: QURAN_WORDING_DIFFERS | I38: 28:86 | J38: آية من فهرس المصحف في الشاملة غُيّرت فيها كلمة واحدة عمدًا | K38: محمد سجاد | L38: مقبول | M38: المحرّف: «نصيرا» بدل «ظهيرا»
A39: t-035 | B39: test | C39: C2 آيات محرفة اللفظ | D39: ar | E39: quran | F39: verifier | G39: منشور اليوم: ﴿وإذا أذقنا الناس رحمة فرحوا بها وإن تصبهم سيئة بما قدمت أيديهم إذا هم ييأسون﴾ — شاركها مع من تحب ولا تنس الدعاء لنا. | H39: QURAN_WORDING_DIFFERS | I39: 30:36 | J39: آية من فهرس المصحف في الشاملة غُيّرت فيها كلمة واحدة عمدًا | L39: لم يراجع | M39: المحرّف: «ييأسون» بدل «يقنطون»
A40: t-036 | B40: test | C40: C2 آيات محرفة اللفظ | D40: ar | E40: quran | F40: verifier | G40: ومن الأدلة على ذلك قوله تعالى: قُلْ مَنْ ذَا الَّذِي يَعْصِمُكُمْ مِنَ اللَّهِ إِنْ أَرَادَ بِكُمْ سُوءًا أَوْ أَرَادَ بِكُمْ رَحْمَةً وَلَا يَجِدُونَ لَهُمْ مِنْ دُونِ اللَّهِ وَلِيًّا وَلَا شَفِيعًا، وهي آية جامعة يحسن بالداعية أن يحفظها. | H40: QURAN_WORDING_DIFFERS | I40: 33:17 | J40: آية من فهرس المصحف في الشاملة غُيّرت فيها كلمة واحدة عمدًا | L40: لم يراجع | M40: المحرّف: «ولا شفيعا» بدل «ولا نصيرا»
...

Sheet التقدّم
A1: الفئة | B1: المستهدف | C1: المُدخل | D1: منها dev | E1: منها مقبول | F1: المتبقي | G1: الحالة المتوقعة غالبًا
A2: C1 آيات عربية صحيحة | B2: 25 | C2: =COUNTIFS(الحالات!$C$5:$C$204,A2,الحالات!$G$5:$G$204,"<>") -> 25 | D2: =COUNTIFS(الحالات!$C$5:$C$204,A2,الحالات!$G$5:$G$204,"<>",الحالات!$B$5:$B$204,"dev") -> 6 | E2: =COUNTIFS(الحالات!$C$5:$C$204,A2,الحالات!$G$5:$G$204,"<>",الحالات!$L$5:$L$204,"مقبول") -> 17 | F2: =MAX(0,B2-C2) -> 0 | G2: QURAN_VERIFIED
A3: C2 آيات محرفة اللفظ | B3: 20 | C3: =COUNTIFS(الحالات!$C$5:$C$204,A3,الحالات!$G$5:$G$204,"<>") -> 20 | D3: =COUNTIFS(الحالات!$C$5:$C$204,A3,الحالات!$G$5:$G$204,"<>",الحالات!$B$5:$B$204,"dev") -> 5 | E3: =COUNTIFS(الحالات!$C$5:$C$204,A3,الحالات!$G$5:$G$204,"<>",الحالات!$L$5:$L$204,"مقبول") -> 10 | F3: =MAX(0,B3-C3) -> 0 | G3: QURAN_WORDING_DIFFERS
A4: C3 آيات مترجمة | B4: 25 | C4: =COUNTIFS(الحالات!$C$5:$C$204,A4,الحالات!$G$5:$G$204,"<>") -> 25 | D4: =COUNTIFS(الحالات!$C$5:$C$204,A4,الحالات!$G$5:$G$204,"<>",الحالات!$B$5:$B$204,"dev") -> 6 | E4: =COUNTIFS(الحالات!$C$5:$C$204,A4,الحالات!$G$5:$G$204,"<>",الحالات!$L$5:$L$204,"مقبول") -> 12 | F4: =MAX(0,B4-C4) -> 0 | G4: QURAN_VERIFIED
A5: C4 أحاديث ثابتة بالعربية | B5: 25 | C5: =COUNTIFS(الحالات!$C$5:$C$204,A5,الحالات!$G$5:$G$204,"<>") -> 25 | D5: =COUNTIFS(الحالات!$C$5:$C$204,A5,الحالات!$G$5:$G$204,"<>",الحالات!$B$5:$B$204,"dev") -> 6 | E5: =COUNTIFS(الحالات!$C$5:$C$204,A5,الحالات!$G$5:$G$204,"<>",الحالات!$L$5:$L$204,"مقبول") -> 11 | F5: =MAX(0,B5-C5) -> 0 | G5: HADITH_AUTHENTIC
A6: C5 أحاديث ثابتة مترجمة | B6: 25 | C6: =COUNTIFS(الحالات!$C$5:$C$204,A6,الحالات!$G$5:$G$204,"<>") -> 25 | D6: =COUNTIFS(الحالات!$C$5:$C$204,A6,الحالات!$G$5:$G$204,"<>",الحالات!$B$5:$B$204,"dev") -> 6 | E6: =COUNTIFS(الحالات!$C$5:$C$204,A6,الحالات!$G$5:$G$204,"<>",الحالات!$L$5:$L$204,"مقبول") -> 12 | F6: =MAX(0,B6-C6) -> 0 | G6: HADITH_AUTHENTIC
A7: C6 أحاديث ضعيفة | B7: 14 | C7: =COUNTIFS(الحالات!$C$5:$C$204,A7,الحالات!$G$5:$G$204,"<>") -> 14 | D7: =COUNTIFS(الحالات!$C$5:$C$204,A7,الحالات!$G$5:$G$204,"<>",الحالات!$B$5:$B$204,"dev") -> 4 | E7: =COUNTIFS(الحالات!$C$5:$C$204,A7,الحالات!$G$5:$G$204,"<>",الحالات!$L$5:$L$204,"مقبول") -> 9 | F7: =MAX(0,B7-C7) -> 0 | G7: HADITH_WEAK
A8: C7 أحاديث موضوعة | B8: 13 | C8: =COUNTIFS(الحالات!$C$5:$C$204,A8,الحالات!$G$5:$G$204,"<>") -> 13 | D8: =COUNTIFS(الحالات!$C$5:$C$204,A8,الحالات!$G$5:$G$204,"<>",الحالات!$B$5:$B$204,"dev") -> 4 | E8: =COUNTIFS(الحالات!$C$5:$C$204,A8,الحالات!$G$5:$G$204,"<>",الحالات!$L$5:$L$204,"مقبول") -> 9 | F8: =MAX(0,B8-C8) -> 0 | G8: HADITH_FABRICATED
A9: C8 أقوال منسوبة لا أصل لها في الفهرس | B9: 38 | C9: =COUNTIFS(الحالات!$C$5:$C$204,A9,الحالات!$G$5:$G$204,"<>") -> 38 | D9: =COUNTIFS(الحالات!$C$5:$C$204,A9,الحالات!$G$5:$G$204,"<>",الحالات!$B$5:$B$204,"dev") -> 10 | E9: =COUNTIFS(الحالات!$C$5:$C$204,A9,الحالات!$G$5:$G$204,"<>",الحالات!$L$5:$L$204,"مقبول") -> 17 | F9: =MAX(0,B9-C9) -> 0 | G9: NOT_FOUND
A10: C9 حالات حرجة من الحزمة | B10: 15 | C10: =COUNTIFS(الحالات!$C$5:$C$204,A10,الحالات!$G$5:$G$204,"<>") -> 15 | D10: =COUNTIFS(الحالات!$C$5:$C$204,A10,الحالات!$G$5:$G$204,"<>",الحالات!$B$5:$B$204,"dev") -> 3 | E10: =COUNTIFS(الحالات!$C$5:$C$204,A10,الحالات!$G$5:$G$204,"<>",الحالات!$L$5:$L$204,"مقبول") -> 9 | F10: =MAX(0,B10-C10) -> 0 | G10: REFER_TO_SCHOLAR
A11: المجموع | B11: =SUM(B2:B10) -> 200 | C11: =SUM(C2:C10) -> 200 | D11: =SUM(D2:D10) -> 50 | E11: =SUM(E2:E10) -> 106 | F11: =SUM(F2:F10) -> 0
A13: الأعمدة C–F تُحسب تلقائيًا من ورقة «الحالات»؛ لا تكتب فيها. الأمثلة الرمادية (EX) غير محسوبة لأنها خارج النطاق.
